2025-03-17 20:01:47,665 INFO    MainThread:33127 [wandb_setup.py:_flush():67] Current SDK version is 0.19.8
2025-03-17 20:01:47,665 INFO    MainThread:33127 [wandb_setup.py:_flush():67] Configure stats pid to 33127
2025-03-17 20:01:47,665 INFO    MainThread:33127 [wandb_setup.py:_flush():67] Loading settings from /Users/jaebincheong/.config/wandb/settings
2025-03-17 20:01:47,665 INFO    MainThread:33127 [wandb_setup.py:_flush():67] Loading settings from /Users/jaebincheong/YBIGTA/25-1_sessions/Week1/25-1-DS-Week-1-Assignment/wandb/settings
2025-03-17 20:01:47,665 INFO    MainThread:33127 [wandb_setup.py:_flush():67] Loading settings from environment variables
2025-03-17 20:01:47,665 INFO    MainThread:33127 [wandb_init.py:setup_run_log_directory():647] Logging user logs to /Users/jaebincheong/YBIGTA/25-1_sessions/Week1/25-1-DS-Week-1-Assignment/wandb/run-20250317_200147-zzh0by1f/logs/debug.log
2025-03-17 20:01:47,665 INFO    MainThread:33127 [wandb_init.py:setup_run_log_directory():648] Logging internal logs to /Users/jaebincheong/YBIGTA/25-1_sessions/Week1/25-1-DS-Week-1-Assignment/wandb/run-20250317_200147-zzh0by1f/logs/debug-internal.log
2025-03-17 20:01:47,665 INFO    MainThread:33127 [wandb_init.py:monkeypatch_ipython():599] configuring jupyter hooks <wandb.sdk.wandb_init._WandbInit object at 0x13f1c44a0>
2025-03-17 20:01:47,665 INFO    MainThread:33127 [wandb_init.py:init():761] calling init triggers
2025-03-17 20:01:47,665 INFO    MainThread:33127 [wandb_init.py:init():766] wandb.init called with sweep_config: {}
config: {'src_vocab_size': 100, 'tgt_vocab_size': 200, 'd_model': 32, 'n_heads': 4, 'd_ff': 64, 'num_encoder_layers': 6, 'num_decoder_layers': 6, 'dropout': 0.1, 'batch_size': 32, 'num_epochs': 50, 'learning_rate': 0.0001, '_wandb': {}}
2025-03-17 20:01:47,665 INFO    MainThread:33127 [wandb_init.py:init():784] starting backend
2025-03-17 20:01:47,665 INFO    MainThread:33127 [wandb_init.py:init():788] sending inform_init request
2025-03-17 20:01:47,688 INFO    MainThread:33127 [backend.py:_multiprocessing_setup():101] multiprocessing start_methods=spawn,fork,forkserver, using: spawn
2025-03-17 20:01:47,688 INFO    MainThread:33127 [wandb_init.py:init():798] backend started and connected
2025-03-17 20:01:47,692 INFO    MainThread:33127 [wandb_run.py:_label_probe_notebook():1204] probe notebook
2025-03-17 20:01:47,693 INFO    MainThread:33127 [wandb_init.py:init():891] updated telemetry
2025-03-17 20:01:47,713 INFO    MainThread:33127 [wandb_init.py:init():915] communicating run to backend with 90.0 second timeout
2025-03-17 20:01:48,200 INFO    MainThread:33127 [wandb_init.py:init():990] starting run threads in backend
2025-03-17 20:01:48,373 INFO    MainThread:33127 [wandb_run.py:_console_start():2375] atexit reg
2025-03-17 20:01:48,373 INFO    MainThread:33127 [wandb_run.py:_redirect():2227] redirect: wrap_raw
2025-03-17 20:01:48,373 INFO    MainThread:33127 [wandb_run.py:_redirect():2292] Wrapping output streams.
2025-03-17 20:01:48,373 INFO    MainThread:33127 [wandb_run.py:_redirect():2315] Redirects installed.
2025-03-17 20:01:48,374 INFO    MainThread:33127 [wandb_init.py:init():1032] run started, returning control to user process
2025-03-17 20:02:20,962 INFO    MainThread:33127 [jupyter.py:save_ipynb():386] not saving jupyter notebook
2025-03-17 20:02:20,962 INFO    MainThread:33127 [wandb_init.py:_pause_backend():564] pausing backend
2025-03-17 20:05:50,186 WARNING MsgRouterThr:33127 [router.py:message_loop():63] message_loop has been closed
Traceback (most recent call last):
  File "/opt/anaconda3/lib/python3.12/site-packages/wandb/sdk/interface/router_sock.py", line 27, in _read_message
    return self._sock_client.read_server_response(timeout=1)
           ^^^^^^^^^^^^^^^^^^^^^^^^^^^^^^^^^^^^^^^^^^^^^^^^^
  File "/opt/anaconda3/lib/python3.12/site-packages/wandb/sdk/lib/sock_client.py", line 235, in read_server_response
    data = self._read_packet_bytes(timeout=timeout)
           ^^^^^^^^^^^^^^^^^^^^^^^^^^^^^^^^^^^^^^^^
  File "/opt/anaconda3/lib/python3.12/site-packages/wandb/sdk/lib/sock_client.py", line 220, in _read_packet_bytes
    raise SockClientClosedError
wandb.sdk.lib.sock_client.SockClientClosedError

The above exception was the direct cause of the following exception:

Traceback (most recent call last):
  File "/opt/anaconda3/lib/python3.12/site-packages/wandb/sdk/interface/router.py", line 56, in message_loop
    msg = self._read_message()
          ^^^^^^^^^^^^^^^^^^^^
  File "/opt/anaconda3/lib/python3.12/site-packages/wandb/sdk/interface/router_sock.py", line 29, in _read_message
    raise MessageRouterClosedError from e
wandb.sdk.interface.router.MessageRouterClosedError
2025-03-17 20:05:50,189 INFO    MsgRouterThr:33127 [mailbox.py:close():129] Closing mailbox, abandoning 1 handles.
